[35mDEBUG   [0m urllib3.util.retry:retry.py:594 Incremented Retry for (url='/pkgs/free/win-64/affine-2.0.0-py27_0.tar.bz2'): Retry(total=2, connect=None, read=None, redirect=None, status=None)
[33mWARNING [0m urllib3.connectionpool:connectionpool.py:812 Retrying (Retry(total=2, connect=None, read=None, redirect=None, status=None)) after connection broken by 'ProtocolError('Connection aborted.', ConnectionResetError(10054, 'An existing connection was forcibly closed by the remote host', None, 10054, None))': /pkgs/free/win-64/affine-2.0.0-py27_0.tar.bz2
[35mDEBUG   [0m urllib3.connectionpool:connectionpool.py:1003 Starting new HTTPS connection (4): repo.anaconda.com:443
[35mDEBUG   [0m urllib3.connectionpool:connectionpool.py:456 https://repo.anaconda.com:443 "GET /pkgs/free/win-64/affine-2.0.0-py27_0.tar.bz2 HTTP/1.1" 200 20579