[35mDEBUG   [0m urllib3.connectionpool:connectionpool.py:228 Starting new HTTP connection (1): repo.anaconda.com:80
[35mDEBUG   [0m urllib3.connectionpool:connectionpool.py:456 http://repo.anaconda.com:80 "GET /pkgs/free/linux-64/cryptography-1.8.1-py36_0.tar.bz2 HTTP/1.1" 301 None
[35mDEBUG   [0m urllib3.util.retry:retry.py:594 Incremented Retry for (url='/pkgs/free/linux-64/cryptography-1.8.1-py36_0.tar.bz2'): Retry(total=2, connect=None, read=None, redirect=None, status=None)
[33mWARNING [0m urllib3.connectionpool:connectionpool.py:812 Retrying (Retry(total=2, connect=None, read=None, redirect=None, status=None)) after connection broken by 'ProtocolError('Connection aborted.', RemoteDisconnected('Remote end closed connection without response'))': /pkgs/free/linux-64/cryptography-1.8.1-py36_0.tar.bz2
[35mDEBUG   [0m urllib3.connectionpool:connectionpool.py:1003 Starting new HTTPS connection (2): repo.anaconda.com:443
[35mDEBUG   [0m urllib3.connectionpool:connectionpool.py:456 https://repo.anaconda.com:443 "GET /pkgs/free/linux-64/cryptography-1.8.1-py36_0.tar.bz2 HTTP/1.1" 200 865871