[32mINFO    [0m conda_build.variants:variants.py:235 Adding in variants from D:\a\conda-build\conda-build\tests\test-recipes\metadata\_pypi_installer_metadata\conda_build_config.yaml
[32mINFO    [0m conda_build.metadata:metadata.py:854 Attempting to finalize metadata for imagesize
[32mINFO    [0m conda_build.source:source.py:46 Source cache directory is: C:\Users\runneradmin\cbtmp\popen-gw1\test_pypi_installer_metadata0\src_cache
[32mINFO    [0m conda_build.source:source.py:71 Downloading source to cache: imagesize-1.1.0_f3832918bc.tar.gz
[32mINFO    [0m conda_build.source:source.py:85 Downloading https://pypi.io/packages/source/i/imagesize/imagesize-1.1.0.tar.gz
[35mDEBUG   [0m urllib3.util.retry:retry.py:594 Incremented Retry for (url='/packages/source/i/imagesize/imagesize-1.1.0.tar.gz'): Retry(total=2, connect=None, read=None, redirect=None, status=None)
[33mWARNING [0m urllib3.connectionpool:connectionpool.py:812 Retrying (Retry(total=2, connect=None, read=None, redirect=None, status=None)) after connection broken by 'ProtocolError('Connection aborted.', ConnectionResetError(10054, 'An existing connection was forcibly closed by the remote host', None, 10054, None))': /packages/source/i/imagesize/imagesize-1.1.0.tar.gz
[32mINFO    [0m conda_build.source:source.py:96 Success
[32mINFO    [0m conda_build.build:build.py:2297 Packaging imagesize
[32mINFO    [0m conda_build.utils:utils.py:2019 Renaming work directory 'C:\Users\runneradmin\cbtmp\popen-gw1\test_pypi_installer_metadata0\imagesize_1668031028334\work' to 'C:\Users\runneradmin\cbtmp\popen-gw1\test_pypi_installer_metadata0\imagesize_1668031028334\work_moved_imagesize-1.1.0-py39_0_win-64_main_build_loop'
[32mINFO    [0m conda_build.utils:utils.py:2026 shutil.move(work)=C:\Users\runneradmin\cbtmp\popen-gw1\test_pypi_installer_metadata0\imagesize_1668031028334\work, dest=C:\Users\runneradmin\cbtmp\popen-gw1\test_pypi_installer_metadata0\imagesize_1668031028334\work_moved_imagesize-1.1.0-py39_0_win-64_main_build_loop)